Workbook

Sheet Master
A1: Main
B2: Brand | C2: Generic | D2: Economics | E2: Indication | F2: MOA
B3: Androgel
B4: Kaletra
B5: Niaspan
B6: Rinvoq, fka ABT-494 | C6: upadacitinib | D6: 1 | E6: Rheumatoid Arthritis | F6: JAK
B7: Survanta
B8: Synagis | D8: AZN
B9: Tricor
B10: Venetoclax, ABT-199
B11: Zemplar
B12: ABT-267 | C12: ombitasvir
B13: ABT-450 | C13: paritaprevir
B14: Restasis (cyclosporine) | C14: Dry Eye | G14: Eyedrop
B15: Orilissa (elagolix) | C15: Uterine Fibroids | F15: NBIX | G15: Oral
B16: Viekira (paritaprevir, ombitasvir) | C16: HCV | F16: 1 | G16: Oral
B17: Durysta (bimatoprost) | C17: Glaucoma | G17: Eyedrop
C21: atrasentan | D21: KDNY | E21: DN
B22: ABT-179 | C22: modimelanotide | E22: AKI | F22: MCR/alpha-MSH
B23: ABT-126 | E23: Alzheimer's | F23: alpha7
B24: ABT-165 | E24: Oncology | F24: VEGF/DLL4
B25: ABT-122 | E25: RA | F25: TNF/IL-17A
B28: ABBV-916 | C28: Alzheimer's | D28: discontinued | E28: aBeta-pE3 mab

Sheet Main
B2: Name | C2: Indication | D2: Approved | E2: MOA | F2: Economics | G2: Administration | H2: IP | J2: Price | K2: 208
B3: Humira (adalimumab) | C3: RA, PSO, CD, UC, PsA, HS, Uveitis, AS | D3: 37621 | E3: TNF | F3: 1 | G3: Subcutaneous | H3: 2024 | J3: Shares | K3: 1771 | L3: Q225
B4: Botox (onabotulinumtoxinA) | C4: Aesthetics, Cervical Dystonia | D4: 33581 | E4: Botulinim | F4: 1 | G4: Subcutaneous | H4: Unclear | J4: MC | K4: =+K3*K2 -> 368368
B5: Imbruvica (ibrutinib) | C5: CLL, GvHD, WM | D5: 41591 | E5: BTK C481 | F5: JNJ | G5: Oral | H5: 46566 | J5: Cash | K5: 6777 | L5: Q225
B6: Skyrizi (risankizumab) | C6: Psoriasis, PsA, Crohn's, UC | D6: 43578 | E6: IL-23 | F6: BI? | G6: Subcutaneous | H6: Biologic | J6: Debt | K6: 70481 | L6: Q225
B7: Rinvoq (upadacitinib) | C7: RA, axSpA, AD, PsA, Crohn's, UC | D7: 44636 | E7: JAK | F7: 1 | G7: Oral | H7: 2030+ | J7: EV | K7: =+K4-K5+K6 -> 432072
B8: Venclexta (venetoclax) | C8: CLL, AML | D8: 42471 | E8: BCL-2 | F8: Roche | G8: Oral | H8: 2030-2033
B9: Lupron Depot (leuprolide) | C9: CRPC | D9: 32534 | F9: 100%? Takeda? | G9: IM
B10: Synthroid (levothyroxine) | C10: Hypothyroidism | D10: 37461 | F10: US only | G10: Oral
B11: Creon | C11: Pancreatic Insufficiency | F11: US only | G11: Oral
B12: Duodopa (carbidopa/levodopa) | C12: Parkinson's Disease | J12: CEO: Robert Michael succeeded Richard Gonzalez.
B13: Qulipta (atogepant) | C13: Migraine | E13: CGRP | F13: 1 | G13: Oral | J13: CFO: Robert A. Michael
B14: Elahere (mirvetuximab soravtansine) | C14: Ovarian Cancer | E14: FRalpha ADC | G14: IV | J14: SVP Discovery: Jonathon Sedgwick
B15: Emrelis (telisotuzumab vedotin) | C15: NSCLC | E15: cMet ADC | G15: IV | J15: Hematology: Mariana Cota Stirner
B16: Vuity (pilocarpine) | C16: Presbyopia | G16: Eyedrop | J16: Ophthalmology: Michael Robinson
B17: Epkinly (epcoritamab) | C17: DLBCL | D17: 45065 | E17: CD3xCD20 | F17: GMAB | G17: IV | J17: CSO: Roopal Thakkar
B18: Juvederm, Volux XC, Voluma XC | C18: Jawline Aesthetics, Temple Hollowing | E18: Dermal HA Filler | J18: Aesthetics: Sara Sangha
B19: Vyalev (foscarbidopa/foslevodopa) | C19: Parkinson's Disease | D19: CRL, approved in EU | E19: Dopamine | F19: 1 | J19: Immunology: Andrew Anisfeld
B20: Vraylar (cariprazine) | C20: Schizophrenia, Bipolar | G20: Oral
D21: Phase
B22: ABBV-400 (telisotuzumab adizutecan) | C22: mCRC, NSCLC, GEA | D22: II | E22: cMet ADC (different ADC) | J22: Acquisitions
B23: tavapadon | C23: Parkinson's Disease | D23: Filing | E23: D1/D5 partial agonist | G23: Oral | J23: Alpine
B24: emraclidine | C24: Schizophrenia | D24: II | E24: M4 PAM | G24: Oral | J24: Allergan
B25: BoNTE (AGN-151586) | C25: Glabellar Lines | D25: III | J25: Capstan
B26: ABBV-383 (etentamig) | C26: Multiple Myeloma | D26: III | E26: BCMA/CD3
B27: ABBV-RGX-314 | C27: AMD, DR | D27: III | E27: VEGF mab gene therapy | F27: RGNX | G27: intravitreal
B28: ABT-981 (lutikizumab) | C28: HS,UC (was OA) | D28: III | E28: IL-1a/1b | F28: 1 | J28: Early Stage Collaborations
B29: ABBV-157 | C29: Psoriasis | D29: II | E29: RORgammaT | F29: 1 | J29: ADARx Pharmaceuticals - siRNA
B30: ABBV-105 | C30: SLE | D30: II | E30: BTK | F30: 1
B31: elsubrutinib ABBV-599 (-105+Rinvoq) | C31: SLE | D31: II | E31: BTK+JAK | F31: 1
B32: ABBV-101 | D32: I | E32: BTK
B33: ABBV-382 | D33: II | E33: alpha4beta7 | F33: 1
B34: ABBV-668 | C34: Autoimmune | D34: II | E34: RIPK1 | F34: 1
B35: ALPN-101 | C35: SLE | D35: II | E35: CD28/ICOS | F35: ALPN
B36: ABBV-0805 | C36: Parkinson's Disease | D36: I | E36: alpha-synuclein | F36: 1
B37: ABBV-1088 | C37: Parkinson's Disease | D37: I | E37: PINK1 | F37: 1
B38: ABBV-8736 | C38: IBD | D38: I | E38: TREM1 mab | F38: 1
B39: ABBV-181 (budigalimab) | C39: Oncology | D39: II | E39: PD-1 | F39: 1
B40: ABBV-151 (livmoniplimab) | C40: Oncology | D40: II | E40: GARP-TGF-B1
B41: ABBV-113 (NX-13) | C41: UC/Crohn's | E41: NLRX1 agonist | F41: Acquired Landos
...

Sheet Model
A1: Main
C2: Q103 | D2: Q203 | E2: Q303 | F2: Q403 | G2: Q104 | H2: Q204 | I2: Q304 | J2: Q404 | K2: Q105 | L2: Q205 | M2: Q305 | N2: Q405 | O2: Q106 | P2: Q206 | Q2: Q306 | R2: Q406 | S2: Q107 | T2: Q207 | U2: Q307 | V2: Q407 | W2: Q108 | X2: Q208 | Y2: Q308 | Z2: Q408 | AA2: Q109 | AB2: Q209 | AC2: Q309 | AD2: Q409 | AE2: Q110 | AF2: Q210 | AG2: Q310 | AH2: Q410 | AI2: Q111 | AJ2: Q211 | AK2: Q311 | AL2: Q411 | AM2: Q112 | AN2: Q212 | AO2: Q312 | AP2: Q412 | AQ2: Q113 | AR2: Q213 | AS2: Q313 | AT2: Q413 | AU2: Q114 | AV2: Q214 | AW2: Q314 | AX2: Q414 | AY2: Q115 | AZ2: Q215 | BA2: Q315 | BB2: Q415 | BC2: Q116 | BD2: Q216 | BE2: Q316 | BF2: Q416 | BG2: Q117 | BH2: Q217 | BI2: Q317 | BJ2: Q417 | BK2: Q118 | BL2: Q218 | BM2: Q318 | BN2: Q418 | BO2: Q119 | BP2: Q219 | BQ2: Q319 | BR2: Q419 | BS2: Q120 | BT2: Q220 | BU2: Q320 | BV2: Q420 | BW2: Q121 | BX2: Q221 | BY2: Q321 | BZ2: Q421 | CA2: Q122 | CB2: Q222 | CC2: Q322 | CD2: Q422 | CE2: Q123 | CF2: Q223 | CG2: Q323 | CH2: Q423 | CI2: Q124 | CJ2: Q224 | CK2: Q324 | CL2: Q424 | CM2: Q125 | CN2: Q225 | CO2: Q325 | CP2: Q425 | CQ2: Q126 | CR2: Q226 | CS2: Q326 | CT2: Q426 | CV2: 2010 | CW2: 2011 | CX2: 2012 | CY2: 2013 | CZ2: =+CY2+1 -> 2014 | DA2: =+CZ2+1 -> 2015 | DB2: =+DA2+1 -> 2016 | DC2: =+DB2+1 -> 2017 | DD2: =+DC2+1 -> 2018 | DE2: =+DD2+1 -> 2019 | DF2: =+DE2+1 -> 2020 | DG2: =+DF2+1 -> 2021 | ... DU2: =+DT2+1 -> 2035
B3: Combined Immunology | AW3: =+AW5+AW8+AW13 -> 3255 | AX3: =+AX5+AX8+AX13 -> 3363 | AY3: =+AY5+AY8+AY13 -> 3111 | AZ3: =+AZ5+AZ8+AZ13 -> 3537 | BA3: =+BA5+BA8+BA13 -> 3647 | BB3: =+BB5+BB8+BB13 -> 3717 | BC3: =+BC5+BC8+BC13 -> 3577 | BD3: =+BD5+BD8+BD13 -> 4149 | ... CT3: =+CT5+CT8+CT13 -> 10478 | CX3: =+CX5+CX8+CX13 -> 9265 | CY3: =+CY5+CY8+CY13 -> 10659 | CZ3: =+CZ5+CZ8+CZ13 -> 12543 | DA3: =+DA5+DA8+DA13 -> 14012 | DB3: =+DB5+DB8+DB13 -> 16078 | DC3: =+DC5+DC8+DC13 -> 18427 | DD3: =+DD5+DD8+DD13 -> 19936 | DE3: =+DE5+DE8+DE13 -> 19571 | ... DP3: =+DP5+DP8+DP13 -> 33788.939
B5: Humira | C5: 30 | D5: 60 | E5: 80 | F5: 110 | G5: 149 | H5: =579-I5-G5 -> 203 | I5: 227 | J5: 273 | K5: 282 | L5: 321 | M5: =1400-N5-L5-K5 -> 356 | N5: 441 | O5: 392 | P5: =1424-Q5-O5 -> 491 | Q5: 541 | R5: 620 | S5: 571 | T5: 735 | U5: 803 | V5: 954 | W5: 878 | X5: 1089 | Y5: 1204 | Z5: 1351 | AA5: =2335-AB5 -> 1024 | AB5: 1311 | AC5: 1491 | AD5: 1662 | AE5: 1397 | AF5: 1593 | AG5: 1679 | AH5: 1879 | AI5: 1646 | AJ5: 1997 | AK5: =7932-AL5-AI5-AJ5 -> 2111 | AL5: 2178 | AM5: 1934 | AN5: 2326 | AO5: 2325 | AP5: 2681 | AQ5: 2244 | AR5: 2606 | AS5: 2770 | AT5: 3039 | AU5: 2637 | AV5: 3288 | AW5: 3255 | AX5: 3363 | AY5: 3111 | AZ5: 3537 | BA5: 3647 | BB5: 3717 | BC5: 3577 | BD5: 4149 | BE5: 4060 | BF5: 4292 | BG5: 4118 | BH5: 4716 | BI5: 4701 | BJ5: 4892 | BK5: 4709 | BL5: 5185 | BM5: 5124 | BN5: 4918 | BO5: 4446 | BP5: 4870 | BQ5: 4936 | BR5: 4917 | BS5: 4703 | BT5: 4837 | BU5: 5140 | BV5: 5152 | BW5: 4867 | BX5: 5068 | BY5: 5425 | BZ5: 5334 | CA5: 4736 | CB5: 5363 | CC5: 5559 | CD5: 5579 | CE5: 3541 | CF5: 4012 | CG5: 3547 | CH5: 3304 | CI5: 2270 | CJ5: 2814 | CK5: 2227 | CL5: 1682 | CM5: 1121 | CN5: 1180 | CO5: 993 | CP5: 1246 | CQ5: =+CM5*0.9 -> 1008.9 | CR5: =+CN5*0.9 -> 1062 | CS5: =+CO5*0.9 -> 893.7 | CT5: =+CP5*0.9 -> 1121.4 | CX5: 9265 | CY5: 10659 | CZ5: 12543 | DA5: 14012 | DB5: 16078 | DC5: 18427 | DD5: =SUM(BK5:BN5) -> 19936 | DE5: =SUM(BO5:BR5) -> 19169 | DF5: =SUM(BS5:BV5) -> 19832 | DG5: =SUM(BW5:BZ5) -> 20694 | DH5: =SUM(CA5:CD5) -> 21237 | DI5: =SUM(CE5:CH5) -> 14404 | DJ5: =SUM(CI5:CL5) -> 8993 | DK5: =SUM(CM5:CP5) -> 4540 | DL5: =+DK5*0.8 -> 3632 | DM5: =+DL5*0.8 -> 2905.6 | DN5: =+DM5*0.5 -> 1452.8 | DO5: =+DN5*0.5 -> 726.4 | DP5: =+DO5*0.5 -> 363.2 | DQ5: =+DP5*0.5 -> 181.6 | DR5: =+DQ5*0.5 -> 90.8 | DS5: =+DR5*0.5 -> 45.4 | DT5: =+DS5*0.5 -> 22.7 | DU5: =+DT5*0.5 -> 11.35
B6: Botox Total | AQ6: - | BG6: 0 | BH6: 0 | BI6: 0 | BJ6: 0 | BK6: 0 | BL6: 0 | BM6: 0 | BN6: 0 | BO6: 0 | BP6: 0 | BQ6: 0 | BR6: 0 | BS6: 0 | BT6: 523 | BU6: 916 | BV6: 1,060 | BW6: 1,009 | BX6: 1,187 | BY6: 1,190 | BZ6: 1,297 | CA6: 1,255 | CB6: 1,373 | CC6: 1,336 | CD6: 1,370 | CE6: 1,378 | CF6: 1,433 | CG6: 1,368 | CH6: 1,494 | CI6: 1,381 | CJ6: 1,543 | CK6: 1,519 | CL6: 1,496 | CM6: 1,422 | CN6: 1,620 | CO6: 1,584 | CP6: 1,707 | CX6: =SUM(BE6:BH6) -> 0 | CY6: =SUM(BF6:BI6) -> 0 | CZ6: =SUM(BG6:BJ6) -> 0 | DA6: =SUM(BH6:BK6) -> 0 | DB6: =SUM(BI6:BL6) -> 0 | DC6: =SUM(BJ6:BM6) -> 0 | DD6: =SUM(BK6:BN6) -> 0 | DE6: =SUM(BO6:BR6) -> 0 | DF6: 2,499 | DG6: 4,683 | DH6: 5,488 | DI6: 5,673 | DJ6: 6,003
B7: Imbruvica | AQ7: - | AZ7: 107 | BA7: 304 | BB7: 343 | BC7: 381 | BD7: 439 | BE7: 501 | BF7: 511 | BG7: 551 | BH7: 626 | BI7: 688 | BJ7: 708 | BK7: 762 | BL7: 850 | BM7: 972 | BN7: 1006 | BO7: 1022 | BP7: 1099 | BQ7: 1257 | BR7: 1296 | BS7: 1232 | BT7: 1288 | BU7: 1370 | BV7: 1424 | BW7: 1268 | BX7: 1381 | BY7: 1374 | BZ7: 1385 | CA7: 1173 | CB7: 1145 | CC7: 1135 | CD7: 1115 | CE7: 878 | CF7: 907 | CG7: 908 | CH7: 903 | CI7: 838 | CJ7: 833 | CK7: 828 | CL7: 848 | CM7: =+CI7*0.95 -> 796.1 | CN7: 754 | CO7: =+CK7*0.95 -> 786.6 | CP7: 671 | CQ7: =+CM7*0.9 -> 716.49 | CR7: =+CN7*0.9 -> 678.6 | CS7: =+CO7*0.9 -> 707.94 | CT7: =+CP7*0.9 -> 603.9 | CX7: 0 | CY7: 0 | CZ7: 0 | DA7: 754 | DB7: 1832 | DC7: 2573 | DD7: =SUM(BK7:BN7) -> 3590 | DE7: =SUM(BO7:BR7) -> 4674 | DF7: =SUM(BS7:BV7) -> 5314 | DG7: =SUM(BW7:BZ7) -> 5408 | DH7: =SUM(CA7:CD7) -> 4568 | DI7: =SUM(CE7:CH7) -> 3596 | DJ7: =SUM(CI7:CL7) -> 3347 | DK7: =SUM(CM7:CP7) -> 3007.7 | DL7: =+DK7*0.9 -> 2706.93 | DM7: =+DL7*0.9 -> 2436.237 | DN7: =+DM7*0.9 -> 2192.6133 | DO7: =+DN7*0.9 -> 1973.352 | DP7: =+DO7*0.9 -> 1776.0168 | DQ7: =+DP7*0.9 -> 1598.4151 | DR7: =+DQ7*0.9 -> 1438.5736 | DS7: =+DR7*0.9 -> 1294.7162 | ... DU7: =+DT7*0.9 -> 1048.7201
B8: Skyrizi | BP8: 48 | BQ8: 91 | BR8: 216 | BS8: 300 | BT8: 330 | BU8: 435 | BV8: 525 | BW8: 574 | BX8: 674 | BY8: 796 | BZ8: 895 | CA8: 940 | CB8: 1252 | CC8: 1397 | CD8: 1576 | CE8: 1360 | CF8: 1883 | CG8: 2126 | CH8: 2394 | CI8: 2008 | CJ8: 2727 | CK8: 3205 | CL8: 3778 | CM8: 3425 | CN8: 4423 | CO8: 4708 | CP8: 5006 | CQ8: =+CM8*1.3 -> 4452.5 | CR8: =+CN8*1.3 -> 5749.9 | CS8: =+CO8*1.3 -> 6120.4 | CT8: =+CP8*1.3 -> 6507.8 | CX8: =SUM(BE8:BH8) -> 0 | CY8: =SUM(BF8:BI8) -> 0 | CZ8: =SUM(BG8:BJ8) -> 0 | DA8: =SUM(BH8:BK8) -> 0 | DB8: =SUM(BI8:BL8) -> 0 | DC8: =SUM(BJ8:BM8) -> 0 | DD8: =SUM(BK8:BN8) -> 0 | DE8: =SUM(BO8:BR8) -> 355 | DF8: =SUM(BS8:BV8) -> 1590 | DG8: =SUM(BW8:BZ8) -> 2939 | DH8: =SUM(CA8:CD8) -> 5165 | DI8: =SUM(CE8:CH8) -> 7763 | DJ8: =SUM(CI8:CL8) -> 11718 | DK8: =SUM(CM8:CP8) -> 17562 | DL8: =+DK8*1.03 -> 18088.86 | DM8: =+DL8*1.03 -> 18631.526 | DN8: =+DM8*1.03 -> 19190.472 | DO8: =+DN8*1.03 -> 19766.186 | DP8: =+DO8*1.03 -> 20359.171 | DQ8: =+DP8*1.03 -> 20969.946 | DR8: =+DQ8*1.03 -> 21599.045 | DS8: =+DR8*1.03 -> 22247.016 | ... DU8: =+DT8*1.03 -> 23601.859
B9: Botox Cosmetic | AQ9: - | BG9: 0 | BH9: 0 | BI9: 0 | BJ9: 0 | BK9: 0 | BL9: 0 | BM9: 0 | BN9: 0 | BO9: 0 | BP9: 0 | BQ9: 0 | BR9: 0 | BS9: 0 | BT9: 226 | BU9: 393 | BV9: 493 | BW9: 477 | BX9: 584 | BY9: 545 | BZ9: 626 | CA9: 641 | CB9: 695 | CC9: 637 | CD9: 642 | CE9: 659 | CF9: 685 | CG9: 620 | CH9: =2682-CG9-CF9-CE9 -> 718 | CI9: 633 | CJ9: 729 | CK9: 671 | CL9: 687 | CM9: 556 | CN9: 692 | CO9: =+CK9*0.97 -> 650.87 | CP9: 717 | CQ9: =+CM9*1.1 -> 611.6 | CR9: =+CN9*1.1 -> 761.2 | CS9: =+CO9*1.1 -> 715.957 | CT9: =+CP9*1.1 -> 788.7 | CX9: =SUM(BE9:BH9) -> 0 | CY9: =SUM(BF9:BI9) -> 0 | CZ9: =SUM(BG9:BJ9) -> 0 | DA9: =SUM(BH9:BK9) -> 0 | DB9: =SUM(BI9:BL9) -> 0 | DC9: =SUM(BJ9:BM9) -> 0 | DD9: =SUM(BK9:BN9) -> 0 | DE9: =SUM(BO9:BR9) -> 0 | DF9: =SUM(BS9:BV9) -> 1112 | DG9: =SUM(BW9:BZ9) -> 2232 | DH9: =SUM(CA9:CD9) -> 2615 | DI9: =SUM(CE9:CH9) -> 2682 | DJ9: =SUM(CI9:CL9) -> 2720 | DK9: =SUM(CM9:CP9) -> 2615.87 | DL9: =+DK9*1.05 -> 2746.6635 | DM9: =+DL9*1.05 -> 2883.9967 | DN9: =+DM9*1.05 -> 3028.1965 | DO9: =+DN9*1.05 -> 3179.6063 | DP9: =+DO9*1.05 -> 3338.5867 | DQ9: =+DP9*1.05 -> 3505.516 | DR9: =+DQ9*1.05 -> 3680.7918 | DS9: =+DR9*1.05 -> 3864.8314 | ... DU9: =+DT9*1.05 -> 4260.9766
B10: Botox Therapeutic | AQ10: - | BG10: 0 | BH10: 0 | BI10: 0 | BJ10: 0 | BK10: 0 | BL10: 0 | BM10: 0 | BN10: 0 | BO10: 0 | BP10: 0 | BQ10: 0 | BR10: 0 | BS10: 0 | BT10: 297 | BU10: 523 | BV10: 567 | BW10: 532 | BX10: 603 | BY10: 645 | BZ10: 671 | CA10: 614 | CB10: 678 | CC10: 699 | CD10: 728 | CE10: 719 | CF10: 748 | CG10: 748 | CH10: =2991-CG10-CF10-CE10 -> 776 | CI10: 748 | CJ10: 814 | CK10: 848 | CL10: 873 | CM10: 866 | CN10: 928 | CO10: =+CK10*1.1 -> 932.8 | CP10: 990 | CQ10: =+CM10*1.1 -> 952.6 | CR10: =+CN10*1.1 -> 1020.8 | CS10: =+CO10*1.1 -> 1026.08 | CT10: =+CP10*1.1 -> 1089 | CX10: =SUM(BE10:BH10) -> 0 | CY10: =SUM(BF10:BI10) -> 0 | CZ10: =SUM(BG10:BJ10) -> 0 | DA10: =SUM(BH10:BK10) -> 0 | DB10: =SUM(BI10:BL10) -> 0 | DC10: =SUM(BJ10:BM10) -> 0 | DD10: =SUM(BK10:BN10) -> 0 | DE10: =SUM(BO10:BR10) -> 0 | DF10: =SUM(BS10:BV10) -> 1387 | DG10: =SUM(BW10:BZ10) -> 2451 | DH10: =SUM(CA10:CD10) -> 2719 | DI10: =SUM(CE10:CH10) -> 2991 | DJ10: =SUM(CI10:CL10) -> 3283 | DK10: =SUM(CM10:CP10) -> 3716.8 | DL10: =+DK10*1.05 -> 3902.64 | DM10: =+DL10*1.05 -> 4097.772 | DN10: =+DM10*1.05 -> 4302.6606 | DO10: =+DN10*1.05 -> 4517.7936 | DP10: =+DO10*1.05 -> 4743.6833 | DQ10: =+DP10*1.05 -> 4980.8675 | DR10: =+DQ10*1.05 -> 5229.9109 | DS10: =+DR10*1.05 -> 5491.4064 | ... DU10: =+DT10*1.05 -> 6054.2755
B11: BonTE | CX11: 0 | CY11: 0 | CZ11: 0 | DA11: 0 | DB11: 0 | DC11: 0 | DD11: 0 | DE11: 0 | DL11: 500 | DM11: 1000 | DN11: 1250 | DO11: 1500 | DP11: 1750 | DQ11: 2000 | DR11: 2200 | DS11: 2400 | DT11: 2600 | DU11: 2800
B12: Venclexta | BM12: 96 | BN12: 124 | BO12: 151 | BP12: 169 | BQ12: 221 | BR12: 251 | BS12: 317 | BT12: 303 | BU12: 352 | BV12: 365 | BW12: 405 | BX12: 435 | BY12: 492 | BZ12: 488 | CA12: 473 | CB12: 505 | CC12: 515 | CD12: 516 | CE12: 538 | CF12: 571 | CG12: 590 | CH12: 589 | CI12: 614 | CJ12: 637 | CK12: 677 | CL12: 655 | CM12: 665 | CN12: 691 | CO12: 726 | CP12: 710 | CQ12: =+CM12*1.1 -> 731.5 | CR12: =+CN12*1.1 -> 760.1 | CS12: =+CO12*1.1 -> 798.6 | CT12: =+CP12*1.1 -> 781 | CX12: 0 | CY12: 0 | CZ12: 0 | DD12: =SUM(BK12:BN12) -> 220 | DE12: =SUM(BO12:BR12) -> 792 | DF12: =SUM(BS12:BV12) -> 1337 | DG12: =SUM(BW12:BZ12) -> 1820 | DH12: =SUM(CA12:CD12) -> 2009 | DI12: =SUM(CE12:CH12) -> 2288 | DJ12: =SUM(CI12:CL12) -> 2583 | DK12: =SUM(CM12:CP12) -> 2792 | DL12: =+DK12*1.03 -> 2875.76 | DM12: =+DL12*1.03 -> 2962.0328 | DN12: =+DM12*1.03 -> 3050.8938 | DO12: =+DN12*1.03 -> 3142.4206 | DP12: =+DO12*0.1 -> 314.24206 | DQ12: =+DP12*0.1 -> 31.424206 | DR12: =+DQ12*0.1 -> 3.1424206 | DS12: =+DR12*0.1 -> 0.31424206 | DT12: =+DS12*0.1 -> 0.031424206 | DU12: =+DT12*0.1 -> 0.0031424206
B13: Rinvoq | BQ13: 14 | BR13: 33 | BS13: 86 | BT13: 149 | BU13: 215 | BV13: 281 | BW13: 303 | BX13: 378 | BY13: 453 | BZ13: 517 | CA13: 465 | CB13: 592 | CC13: 695 | CD13: 770 | CE13: 686 | CF13: 918 | CG13: 1110 | CH13: 1255 | CI13: 1093 | CJ13: 1430 | CK13: 1614 | CL13: 1834 | CM13: 1718 | CN13: 2028 | CO13: 2184 | CP13: 2374 | CQ13: =+CM13*1.2 -> 2061.6 | CR13: =+CN13*1.2 -> 2433.6 | CS13: =+CO13*1.2 -> 2620.8 | CT13: =+CP13*1.2 -> 2848.8 | CX13: =SUM(BE13:BH13) -> 0 | CY13: =SUM(BF13:BI13) -> 0 | CZ13: =SUM(BG13:BJ13) -> 0 | DA13: =SUM(BH13:BK13) -> 0 | DB13: =SUM(BI13:BL13) -> 0 | DC13: =SUM(BJ13:BM13) -> 0 | DD13: =SUM(BK13:BN13) -> 0 | DE13: =SUM(BO13:BR13) -> 47 | DF13: =SUM(BS13:BV13) -> 731 | DG13: =SUM(BW13:BZ13) -> 1651 | DH13: =SUM(CA13:CD13) -> 2522 | DI13: =SUM(CE13:CH13) -> 3969 | DJ13: =SUM(CI13:CL13) -> 5971 | DK13: =SUM(CM13:CP13) -> 8304 | DL13: =+DK13*1.2 -> 9964.8 | DM13: =+DL13*1.2 -> 11957.76 | DN13: =+DM13*1.03 -> 12316.493 | DO13: =+DN13*1.03 -> 12685.988 | DP13: =+DO13*1.03 -> 13066.567 | DQ13: =+DP13*0.1 -> 1306.6567 | DR13: =+DQ13*0.1 -> 130.66567 | DS13: =+DR13*0.1 -> 13.066567 | DT13: =+DS13*0.1 -> 1.3066567 | DU13: =+DT13*0.1 -> 0.13066567
B14: Vraylar | AQ14: - | BG14: 0 | BH14: 0 | BI14: 0 | BJ14: 0 | BK14: 0 | BL14: 0 | BM14: 0 | BN14: 0 | BO14: 0 | BP14: 0 | BQ14: 0 | BR14: 0 | BS14: 0 | BT14: 192 | BU14: 358 | BV14: 401 | BW14: 346 | BX14: 432 | BY14: 461 | BZ14: 489 | CA14: 427 | CB14: 492 | CC14: 554 | CD14: 565 | CE14: 561 | CF14: 658 | CG14: 751 | CH14: 789 | CI14: 694 | CJ14: 774 | CK14: 875 | CL14: 924 | CM14: 765 | CN14: 900 | CO14: 934 | CP14: 1022 | CQ14: =+CM14*1.2 -> 918 | CR14: =+CN14*1.2 -> 1080 | CS14: =+CO14*1.2 -> 1120.8 | CT14: =+CP14*1.2 -> 1226.4 | CX14: =SUM(BE14:BH14) -> 0 | CY14: =SUM(BF14:BI14) -> 0 | CZ14: =SUM(BG14:BJ14) -> 0 | DA14: =SUM(BH14:BK14) -> 0 | DB14: =SUM(BI14:BL14) -> 0 | DC14: =SUM(BJ14:BM14) -> 0 | DD14: =SUM(BK14:BN14) -> 0 | DE14: =SUM(BO14:BR14) -> 0 | DF14: =SUM(BS14:BV14) -> 951 | DG14: =SUM(BW14:BZ14) -> 1728 | DH14: =SUM(CA14:CD14) -> 2038 | DI14: =SUM(CE14:CH14) -> 2759 | DJ14: =SUM(CI14:CL14) -> 3267 | DK14: =SUM(CM14:CP14) -> 3621 | DL14: =+DK14*1.03 -> 3729.63 | DM14: =+DL14*1.03 -> 3841.5189 | DN14: =+DM14*1.03 -> 3956.7645 | DO14: =+DN14*1.03 -> 4075.4674 | DP14: =+DO14*0.1 -> 407.54674 | DQ14: =+DP14*0.1 -> 40.754674 | DR14: =+DQ14*0.1 -> 4.0754674 | DS14: =+DR14*0.1 -> 0.40754674 | DT14: =+DS14*0.1 -> 0.040754674 | DU14: =+DT14*0.1 -> 0.0040754674
B15: Juvederm | AQ15: - | BG15: 0 | BH15: 0 | BI15: 0 | BJ15: 0 | BK15: 0 | BL15: 0 | BM15: 0 | BN15: 0 | BO15: 0 | BP15: 0 | BQ15: 0 | BR15: 0 | BS15: 0 | BT15: 113 | BU15: 274 | BV15: 331 | BW15: 321 | BX15: 428 | BY15: 354 | BZ15: 252 | CA15: 410 | CB15: 344 | CC15: 352 | CD15: 322 | CE15: 355 | CF15: 368 | CG15: 321 | CH15: 334 | CI15: 297 | CJ15: 343 | CK15: 258 | CL15: 279 | CM15: 231 | CN15: 260 | CO15: 253 | CP15: 249 | CQ15: =+CM15 -> 231 | CR15: =+CN15 -> 260 | CS15: =+CO15 -> 253 | CT15: =+CP15 -> 249 | CX15: =SUM(BE15:BH15) -> 0 | CY15: =SUM(BF15:BI15) -> 0 | CZ15: =SUM(BG15:BJ15) -> 0 | DA15: =SUM(BH15:BK15) -> 0 | DB15: =SUM(BI15:BL15) -> 0 | DC15: =SUM(BJ15:BM15) -> 0 | DD15: =SUM(BK15:BN15) -> 0 | DE15: =SUM(BO15:BR15) -> 0 | DF15: =SUM(BS15:BV15) -> 718 | DG15: =SUM(BW15:BZ15) -> 1355 | DH15: =SUM(CA15:CD15) -> 1428 | DI15: =SUM(CE15:CH15) -> 1378 | DJ15: =SUM(CI15:CL15) -> 1177 | DK15: =SUM(CM15:CP15) -> 993 | DL15: =+DK15*1.05 -> 1042.65 | DM15: =+DL15*1.05 -> 1094.7825 | DN15: =+DM15*1.05 -> 1149.5216 | DO15: =+DN15*1.05 -> 1206.9977 | DP15: =+DO15*1.05 -> 1267.3476 | DQ15: =+DP15*1.05 -> 1330.715 | DR15: =+DQ15*1.05 -> 1397.2507 | DS15: =+DR15*1.05 -> 1467.1133 | ... DU15: =+DT15*1.05 -> 1617.4924
B16: Mavyret | AQ16: 0 | BG16: 0 | BH16: 0 | BI16: 276 | BJ16: 510 | BK16: 919 | BL16: 973 | BM16: 839 | BN16: 819 | BO16: 790 | BP16: 780 | BQ16: 695 | BR16: 628 | BS16: 559 | BT16: 376 | BU16: 414 | BV16: 481 | BW16: 415 | BX16: 442 | BY16: 426 | BZ16: 427 | CA16: 380 | CB16: 398 | CC16: 383 | CD16: 380 | CE16: 364 | CF16: 387 | CG16: 370 | CH16: 309 | CI16: 349 | CJ16: 369 | CK16: 302 | CL16: 291 | CM16: 306 | CN16: 375 | CO16: 312 | CP16: 324 | CQ16: =+CM16 -> 306 | CR16: =+CN16 -> 375 | CS16: =+CO16 -> 312 | CT16: =+CP16 -> 324 | DD16: =SUM(BK16:BN16) -> 3550 | DE16: =SUM(BO16:BR16) -> 2893 | DF16: =SUM(BS16:BV16) -> 1830 | DG16: =SUM(BW16:BZ16) -> 1710 | DH16: =SUM(CA16:CD16) -> 1541 | DI16: =SUM(CE16:CH16) -> 1430 | DJ16: =SUM(CI16:CL16) -> 1311 | DK16: =SUM(CM16:CP16) -> 1317 | DL16: =+DK16*0.7 -> 921.9 | DM16: =+DL16*0.7 -> 645.33 | DN16: =+DM16*0.7 -> 451.731 | DO16: =+DN16*0.7 -> 316.2117 | DP16: =+DO16*0.7 -> 221.34819 | DQ16: =+DP16*0.7 -> 154.94373 | DR16: =+DQ16*0.7 -> 108.46061 | DS16: =+DR16*0.7 -> 75.922429 | ... DU16: =+DT16*0.7 -> 37.20199
B17: Other Aesthetics | AQ17: - | BG17: 0 | BH17: 0 | BI17: 0 | BJ17: 0 | BK17: 0 | BL17: 0 | BM17: 0 | BN17: 0 | BO17: 0 | BP17: 0 | BQ17: 0 | BR17: 0 | BS17: 0 | BT17: 142 | BU17: 300 | BV17: 318 | BW17: 343 | BX17: 422 | BY17: 352 | BZ17: 349 | CA17: 323 | CB17: 332 | CC17: 312 | CD17: 323 | CE17: 286 | CF17: 331 | CG17: 298 | CH17: 319 | CI17: 319 | CJ17: 318 | CK17: 310 | CL17: 332 | CM17: 315 | CN17: 327 | CO17: 303 | CP17: 320 | CQ17: =+CM17 -> 315 | CR17: =+CN17 -> 327 | CS17: =+CO17 -> 303 | CT17: =+CP17 -> 320 | DD17: =SUM(BK17:BN17) -> 0 | DE17: =SUM(BO17:BR17) -> 0 | DF17: =SUM(BS17:BV17) -> 760 | DG17: =SUM(BW17:BZ17) -> 1466 | DH17: =SUM(CA17:CD17) -> 1290 | DI17: =SUM(CE17:CH17) -> 1234 | DJ17: =SUM(CI17:CL17) -> 1279 | DK17: =SUM(CM17:CP17) -> 1265 | DL17: =+DK17*0.9 -> 1138.5 | DM17: =+DL17*0.9 -> 1024.65 | DN17: =+DM17*0.9 -> 922.185 | DO17: =+DN17*0.9 -> 829.9665 | DP17: =+DO17*0.9 -> 746.96985 | DQ17: =+DP17*0.9 -> 672.27287 | DR17: =+DQ17*0.9 -> 605.04558 | DS17: =+DR17*0.9 -> 544.54102 | ... DU17: =+DT17*0.9 -> 441.07823
B18: Creon | AM18: 146 | AN18: 162 | AO18: 163 | AP18: 188 | AQ18: 90 | AR18: 106 | AS18: 101 | AT18: 115 | AU18: 107 | AV18: 110 | AW18: 148 | AX18: 151 | AY18: 127 | AZ18: 159 | BA18: 161 | BB18: 185 | BC18: 150 | BD18: 180 | BE18: 187 | BF18: 213 | BG18: 185 | BH18: 196 | BI18: 215 | BJ18: 235 | BK18: 209 | BL18: 219 | BM18: 239 | BN18: 261 | BO18: 227 | BP18: 257 | BQ18: 265 | BR18: 292 | BS18: 276 | BT18: 252 | BU18: 282 | BV18: 304 | BW18: 274 | BX18: 280 | BY18: 310 | BZ18: 327 | CA18: 287 | CB18: 318 | CC18: 336 | CD18: 337 | CE18: 305 | CF18: 282 | CG18: 305 | CH18: 376 | CI18: 285 | CJ18: 372 | CK18: 338 | CL18: 388 | CM18: 355 | CN18: 404 | CO18: 368 | CP18: 385 | CQ18: =+CM18 -> 355 | CR18: =+CN18 -> 404 | CS18: =+CO18 -> 368 | CT18: =+CP18 -> 385 | CX18: 353 | CY18: 412 | CZ18: 516 | DA18: 632 | DB18: 730 | DC18: 831 | DD18: =SUM(BK18:BN18) -> 928 | DE18: =SUM(BO18:BR18) -> 1041 | DF18: =SUM(BS18:BV18) -> 1114 | DG18: =SUM(BW18:BZ18) -> 1191 | DH18: =SUM(CA18:CD18) -> 1278 | DI18: =SUM(CE18:CH18) -> 1268 | DJ18: =SUM(CI18:CL18) -> 1383 | DK18: =SUM(CM18:CP18) -> 1512 | DL18: =+DK18*1.03 -> 1557.36 | DM18: =+DL18*1.03 -> 1604.0808 | DN18: =+DM18*1.03 -> 1652.2032 | DO18: =+DN18*1.03 -> 1701.7693 | DP18: =+DO18*1.03 -> 1752.8224 | DQ18: =+DP18*1.03 -> 1805.4071 | DR18: =+DQ18*1.03 -> 1859.5693 | DS18: =+DR18*1.03 -> 1915.3564 | ... DU18: =+DT18*1.03 -> 2032.0016
B19: Other Eye Care | BG19: 0 | BH19: 0 | BI19: 0 | BJ19: 0 | BK19: 0 | BL19: 0 | BM19: 0 | BN19: 0 | BO19: 0 | BP19: 0 | BQ19: 0 | BR19: 0 | BS19: 0 | BT19: 128 | BU19: 269 | BV19: 296 | BW19: 276 | BX19: 301 | BY19: 286 | BZ19: 306 | CA19: 278 | CB19: 217 | CC19: =287-CC32 -> 181 | CD19: =283-CD32 -> 71 | CE19: 200 | CF19: 215 | CG19: 207 | CH19: 181 | CI19: 200 | CJ19: 225 | CK19: 207 | CL19: 215 | CM19: 217 | CN19: 250 | CO19: 248 | CP19: 294 | CQ19: =+CM19 -> 217 | CR19: =+CN19 -> 250 | CS19: =+CO19 -> 248 | CT19: =+CP19 -> 294 | DD19: =SUM(BK19:BN19) -> 0 | DE19: =SUM(BO19:BR19) -> 0 | DF19: =SUM(BS19:BV19) -> 693 | DG19: =SUM(BW19:BZ19) -> 1169 | DH19: =SUM(CA19:CD19) -> 747 | DI19: =SUM(CE19:CH19) -> 803 | DJ19: =SUM(CI19:CL19) -> 847 | DK19: =SUM(CM19:CP19) -> 1009 | DL19: =+DK19*0.9 -> 908.1 | DM19: =+DL19*0.9 -> 817.29 | DN19: =+DM19*0.9 -> 735.561 | DO19: =+DN19*0.9 -> 662.0049 | DP19: =+DO19*0.9 -> 595.80441 | DQ19: =+DP19*0.9 -> 536.22397 | DR19: =+DQ19*0.9 -> 482.60157 | DS19: =+DR19*0.9 -> 434.34141 | ... DU19: =+DT19*0.9 -> 351.81655
B20: Restasis | BG20: 0 | BH20: 0 | BI20: 0 | BJ20: 0 | BK20: 0 | BL20: 0 | BM20: 0 | BN20: 0 | BO20: 0 | BP20: 0 | BQ20: 0 | BR20: 0 | BS20: 0 | BT20: 144 | BU20: 299 | BV20: 344 | BW20: 280 | BX20: 327 | BY20: 319 | BZ20: 364 | CA20: 246 | CB20: 168 | CC20: 142 | CD20: 110 | CE20: 92 | CF20: 99 | CG20: 117 | CH20: 128 | CI20: 57 | CJ20: 32 | CK20: 21 | CL20: 114 | DD20: =SUM(BK20:BN20) -> 0 | DE20: =SUM(BO20:BR20) -> 0 | DF20: =SUM(BS20:BV20) -> 787 | DG20: =SUM(BW20:BZ20) -> 1290 | DH20: =SUM(CA20:CD20) -> 666 | DI20: =SUM(CE20:CH20) -> 436 | DJ20: =SUM(CI20:CL20) -> 224 | DK20: =SUM(CM20:CP20) -> 0 | DL20: =+DK20*0.9 -> 0 | DM20: =+DL20*0.9 -> 0 | DN20: =+DM20*0.9 -> 0 | DO20: =+DN20*0.9 -> 0 | DP20: =+DO20*0.9 -> 0 | DQ20: =+DP20*0.9 -> 0 | DR20: =+DQ20*0.9 -> 0 | DS20: =+DR20*0.9 -> 0 | ... DU20: =+DT20*0.9 -> 0
B21: Linzess | BG21: 0 | BH21: 0 | BI21: 0 | BJ21: 0 | BK21: 0 | BL21: 0 | BM21: 0 | BN21: 0 | BO21: 0 | BP21: 0 | BQ21: 0 | BR21: 0 | BS21: 0 | BT21: 133 | BU21: 248 | BV21: 286 | BW21: 222 | BX21: 268 | BY21: 261 | BZ21: 287 | CA21: 240 | CB21: 255 | CC21: 271 | CD21: 269 | CE21: 259 | CF21: 278 | CG21: 288 | CH21: 283 | CI21: 266 | CJ21: 221 | CK21: 234 | CL21: 233 | CM21: 148 | CN21: 258 | CO21: 326 | CP21: 175 | CQ21: =+CP21-5 -> 170 | CR21: =+CQ21-5 -> 165 | CS21: =+CR21-5 -> 160 | CT21: =+CS21-5 -> 155 | DD21: =SUM(BK21:BN21) -> 0 | DE21: =SUM(BO21:BR21) -> 0 | DF21: =SUM(BS21:BV21) -> 667 | DG21: =SUM(BW21:BZ21) -> 1038 | DH21: =SUM(CA21:CD21) -> 1035 | DI21: =SUM(CE21:CH21) -> 1108 | DJ21: =SUM(CI21:CL21) -> 954 | DK21: =SUM(CM21:CP21) -> 907 | DL21: =+DK21*0.5 -> 453.5 | DM21: =+DL21*0.5 -> 226.75 | DN21: =+DM21*0.5 -> 113.375 | DO21: =+DN21*0.5 -> 56.6875 | DP21: =+DO21*0.5 -> 28.34375 | DQ21: =+DP21*0.5 -> 14.171875 | DR21: =+DQ21*0.5 -> 7.0859375 | DS21: =+DR21*0.5 -> 3.5429688 | ... DU21: =+DT21*0.5 -> 0.88574219
B22: Other CNS | BG22: 0 | BH22: 0 | BI22: 0 | BJ22: 0 | BK22: 0 | BL22: 0 | BM22: 0 | BN22: 0 | BO22: 0 | BP22: 0 | BQ22: 0 | BR22: 0 | BS22: 0 | BT22: 105 | BU22: 207 | BV22: 227 | BW22: 160 | BX22: 171 | BY22: 171 | BZ22: 183 | CA22: 177 | CB22: 150 | CC22: 87 | CD22: 61 | CE22: 79 | CF22: 70 | CG22: 61 | CH22: 66 | CI22: 74 | CJ22: 80 | CK22: 84 | CL22: 100 | CM22: =+CI22 -> 74 | CN22: 55 | CO22: 46 | CP22: 47 | CQ22: =+CP22 -> 47 | CR22: =+CQ22 -> 47 | CS22: =+CR22 -> 47 | CT22: =+CS22 -> 47 | DD22: =SUM(BK22:BN22) -> 0 | DE22: =SUM(BO22:BR22) -> 0 | DF22: =SUM(BS22:BV22) -> 539 | DG22: =SUM(BW22:BZ22) -> 685 | DH22: =SUM(CA22:CD22) -> 475 | DI22: =SUM(CE22:CH22) -> 276 | DJ22: =SUM(CI22:CL22) -> 338 | DK22: =SUM(CM22:CP22) -> 222 | DL22: =+DK22*0.9 -> 199.8 | DM22: =+DL22*0.9 -> 179.82 | DN22: =+DM22*0.9 -> 161.838 | DO22: =+DN22*0.9 -> 145.6542 | DP22: =+DO22*0.9 -> 131.08878 | DQ22: =+DP22*0.9 -> 117.9799 | DR22: =+DQ22*0.9 -> 106.18191 | DS22: =+DR22*0.9 -> 95.563721 | ... DU22: =+DT22*0.9 -> 77.406614
B23: Lumigan/Ganfort | BG23: 0 | BH23: 0 | BI23: 0 | BJ23: 0 | BK23: 0 | BL23: 0 | BM23: 0 | BN23: 0 | BO23: 0 | BP23: 0 | BQ23: 0 | BR23: 0 | BS23: 0 | BT23: 76 | BU23: 149 | BV23: 153 | BW23: 143 | BX23: 149 | BY23: 138 | BZ23: 149 | CA23: 140 | CB23: 130 | CC23: 121 | CD23: 123 | CE23: 130 | CF23: 119 | CG23: 91 | CH23: 92 | CI23: 91 | CJ23: 103 | CK23: 116 | CL23: 119 | CM23: 106 | CN23: 103 | CO23: 97 | CP23: 104 | CQ23: =+CM23 -> 106 | CR23: =+CN23 -> 103 | CS23: =+CO23 -> 97 | CT23: =+CP23 -> 104 | DD23: =SUM(BK23:BN23) -> 0 | DE23: =SUM(BO23:BR23) -> 0 | DF23: =SUM(BS23:BV23) -> 378 | DG23: =SUM(BW23:BZ23) -> 579 | DH23: =SUM(CA23:CD23) -> 514 | DI23: =SUM(CE23:CH23) -> 432 | DJ23: =SUM(CI23:CL23) -> 429 | DK23: =SUM(CM23:CP23) -> 410 | DL23: =+DK23*0.9 -> 369 | DM23: =+DL23*0.9 -> 332.1 | DN23: =+DM23*0.9 -> 298.89 | DO23: =+DN23*0.9 -> 269.001 | DP23: =+DO23*0.9 -> 242.1009 | DQ23: =+DP23*0.9 -> 217.89081 | DR23: =+DQ23*0.9 -> 196.10173 | DS23: =+DR23*0.9 -> 176.49156 | ... DU23: =+DT23*0.9 -> 142.95816
B24: Ubrelvy | BG24: 0 | BH24: 0 | BI24: 0 | BJ24: 0 | BK24: 0 | BL24: 0 | BM24: 0 | BN24: 0 | BO24: 0 | BP24: 0 | BQ24: 0 | BR24: 0 | BS24: 0 | BT24: 22 | BU24: 38 | BV24: 65 | BW24: 81 | BX24: 126 | BY24: 162 | BZ24: 183 | CA24: 138 | CB24: 185 | CC24: 160 | CD24: 197 | CE24: 152 | CF24: 196 | CG24: 233 | CH24: 234 | CI24: 203 | CJ24: 231 | CK24: 269 | CL24: 303 | CM24: 240 | CN24: 338 | CO24: 354 | CP24: 339 | CQ24: =+CP24+5 -> 344 | CR24: =+CQ24+5 -> 349 | CS24: =+CR24+5 -> 354 | CT24: =+CS24+5 -> 359 | DD24: =SUM(BK24:BN24) -> 0 | DE24: =SUM(BO24:BR24) -> 0 | DF24: =SUM(BS24:BV24) -> 125 | DG24: =SUM(BW24:BZ24) -> 552 | DH24: =SUM(CA24:CD24) -> 680 | DI24: =SUM(CE24:CH24) -> 815 | DJ24: =SUM(CI24:CL24) -> 1006 | DK24: =SUM(CM24:CP24) -> 1271 | DL24: =+DK24*1.2 -> 1525.2 | DM24: =+DL24*1.1 -> 1677.72 | DN24: =+DM24*1.1 -> 1845.492 | DO24: =+DN24*1.03 -> 1900.8568 | DP24: =+DO24*0.1 -> 190.08568 | DQ24: =+DP24*0.1 -> 19.008568 | DR24: =+DQ24*0.1 -> 1.9008568 | DS24: =+DR24*0.1 -> 0.19008568 | DT24: =+DS24*0.1 -> 0.019008568 | DU24: =+DT24*0.1 -> 0.0019008568
B25: Duodopa | AO25: 37 | AQ25: 39 | AR25: 44 | AS25: 46 | AT25: 49 | AU25: 52 | AV25: 56 | AW25: 56 | AX25: 56 | AY25: 53 | AZ25: 55 | BA25: 61 | BB25: 62 | BC25: 68 | BD25: 73 | BE25: 74 | BF25: 78 | BG25: 80 | BH25: 81 | BI25: 94 | BJ25: 100 | BK25: 103 | BL25: 108 | BM25: 106 | BN25: 113 | BO25: 111 | BP25: 115 | BQ25: 117 | BR25: 118 | BS25: 124 | BT25: 118 | BU25: 123 | BV25: 129 | BW25: 129 | BX25: 127 | BY25: 127 | BZ25: 128 | CA25: 121 | CB25: 120 | CC25: 110 | CD25: 107 | CE25: 118 | CF25: 117 | CG25: 118 | CH25: 115 | CI25: 115 | CJ25: 113 | CK25: 111 | CL25: 108 | CM25: 96 | CN25: 97 | CO25: 96 | CP25: 92 | CQ25: =+CM25 -> 96 | CR25: =+CN25 -> 97 | CS25: =+CO25 -> 96 | CT25: =+CP25 -> 92 | CX25: 149 | CY25: 178 | CZ25: 220 | DA25: 231 | DB25: 293 | DC25: 355 | DD25: =SUM(BK25:BN25) -> 430 | DE25: =SUM(BO25:BR25) -> 461 | DF25: =SUM(BS25:BV25) -> 494 | DG25: =SUM(BW25:BZ25) -> 511 | DH25: =SUM(CA25:CD25) -> 458 | DI25: =SUM(CE25:CH25) -> 468 | DJ25: =SUM(CI25:CL25) -> 447 | DK25: =SUM(CM25:CP25) -> 381 | DL25: =+DK25*0.9 -> 342.9 | DM25: =+DL25*0.9 -> 308.61 | DN25: =+DM25*0.9 -> 277.749 | DO25: =+DN25*0.9 -> 249.9741 | DP25: =+DO25*0.9 -> 224.97669 | DQ25: =+DP25*0.9 -> 202.47902 | DR25: =+DQ25*0.9 -> 182.23112 | DS25: =+DR25*0.9 -> 164.00801 | ... DU25: =+DT25*0.9 -> 132.84649
B26: Alphagan/Combigan | BG26: 0 | BH26: 0 | BI26: 0 | BJ26: 0 | BK26: 0 | BL26: 0 | BM26: 0 | BN26: 0 | BO26: 0 | BP26: 0 | BQ26: 0 | BR26: 0 | BS26: 0 | BT26: 69 | BU26: 123 | BV26: 134 | BW26: 118 | BX26: 142 | BY26: 128 | BZ26: 141 | CA26: 107 | CB26: 92 | CC26: 73 | CD26: 74 | CE26: 71 | CF26: 65 | CG26: 70 | CH26: 66 | CI26: 59 | CJ26: 49 | CK26: 62 | CL26: 78 | CM26: 60 | CN26: 36 | CO26: 47 | CP26: 54 | CQ26: =+CM26 -> 60 | CR26: =+CN26 -> 36 | CS26: =+CO26 -> 47 | CT26: =+CP26 -> 54 | DD26: =SUM(BK26:BN26) -> 0 | DE26: =SUM(BO26:BR26) -> 0 | DF26: =SUM(BS26:BV26) -> 326 | DG26: =SUM(BW26:BZ26) -> 529 | DH26: =SUM(CA26:CD26) -> 346 | DI26: =SUM(CE26:CH26) -> 272 | DJ26: =SUM(CI26:CL26) -> 248 | DK26: =SUM(CM26:CP26) -> 197 | DL26: =+DK26*0.9 -> 177.3 | DM26: =+DL26*0.9 -> 159.57 | DN26: =+DM26*0.9 -> 143.613 | DO26: =+DN26*0.9 -> 129.2517 | DP26: =+DO26*0.9 -> 116.32653 | DQ26: =+DP26*0.9 -> 104.69388 | DR26: =+DQ26*0.9 -> 94.224489 | DS26: =+DR26*0.9 -> 84.80204 | ... DU26: =+DT26*0.9 -> 68.689653
B27: Qulipta | BG27: 0 | BH27: 0 | BI27: 0 | BJ27: 0 | BK27: 0 | BL27: 0 | BM27: 0 | BN27: 0 | BO27: 0 | BP27: 0 | BQ27: 0 | BR27: 0 | BS27: 0 | BT27: 0 | BU27: 0 | BV27: 0 | BW27: 0 | BX27: 0 | BY27: 0 | BZ27: 0 | CA27: 11 | CB27: 33 | CC27: 62 | CD27: 52 | CE27: 66 | CF27: 96 | CG27: 132 | CH27: 114 | CI27: 131 | CJ27: 150 | CK27: 176 | CL27: 201 | CM27: 193 | CN27: 267 | CO27: 288 | CP27: 288 | CQ27: =+CP27+5 -> 293 | CR27: =+CQ27+5 -> 298 | CS27: =+CR27+5 -> 303 | CT27: =+CS27+5 -> 308 | DD27: =SUM(BK27:BN27) -> 0 | DE27: =SUM(BO27:BR27) -> 0 | DF27: =SUM(BS27:BV27) -> 0 | DG27: =SUM(BW27:BZ27) -> 0 | DH27: =SUM(CA27:CD27) -> 158 | DI27: =SUM(CE27:CH27) -> 408 | DJ27: =SUM(CI27:CL27) -> 658 | DK27: =SUM(CM27:CP27) -> 1036 | DL27: =+DK27*1.2 -> 1243.2 | DM27: =+DL27*1.1 -> 1367.52 | DN27: =+DM27*1.1 -> 1504.272 | DO27: =+DN27*1.03 -> 1549.4002 | DP27: =+DO27*0.1 -> 154.94002 | DQ27: =+DP27*0.1 -> 15.494002 | DR27: =+DQ27*0.1 -> 1.5494002 | DS27: =+DR27*0.1 -> 0.15494002 | DT27: =+DS27*0.1 -> 0.015494002 | DU27: =+DT27*0.1 -> 0.0015494002
B28: Elahere | CI28: 64 | CJ28: 128 | CK28: 139 | CL28: 148 | CM28: 179 | CN28: 159 | CO28: 170 | CP28: 182 | CQ28: =+CP28+5 -> 187 | CR28: =+CQ28+5 -> 192 | CS28: =+CR28+5 -> 197 | CT28: =+CS28+5 -> 202 | DJ28: =SUM(CI28:CL28) -> 479 | DK28: =SUM(CM28:CP28) -> 690 | DL28: =+DK28*1.1 -> 759 | DM28: =+DL28*1.1 -> 834.9 | DN28: =+DM28*1.1 -> 918.39 | DO28: =+DN28*1.1 -> 1010.229 | DP28: =+DO28*1.1 -> 1111.2519 | DQ28: =+DP28*1.1 -> 1222.3771 | DR28: =+DQ28*1.1 -> 1344.6148 | DS28: =+DR28*1.1 -> 1479.0763 | ... DU28: =+DT28*1.1 -> 1789.6823
B29: teliso-V | DK29: =SUM(CM29:CP29) -> 0 | DL29: 500 | DM29: 800 | DN29: 1200 | DO29: 1500 | DP29: 1800 | DQ29: 2000 | DR29: 2200 | DS29: 2400 | DT29: 2600 | DU29: 2800
B30: Other Oncology | CP30: 20 | CQ30: =+CP30 -> 20 | CR30: =+CQ30 -> 20 | CS30: =+CR30 -> 20 | CT30: =+CS30 -> 20
B31: Epkinly | CG31: 14 | CH31: 17 | CI31: 27 | CJ31: 36 | CK31: 43 | CL31: 40 | CM31: 51 | CN31: 70 | CO31: 69 | CP31: 81 | CQ31: =+CP31+3 -> 84 | CR31: =+CQ31+3 -> 87 | CS31: =+CR31+3 -> 90 | CT31: =+CS31+3 -> 93 | DI31: =SUM(CE31:CH31) -> 31 | DJ31: =SUM(CI31:CL31) -> 146 | DK31: =SUM(CM31:CP31) -> 271 | DL31: =+DK31*1.4 -> 379.4 | DM31: =+DL31*1.3 -> 493.22 | DN31: =+DM31*1.2 -> 591.864 | DO31: =+DN31*1.2 -> 710.2368 | DP31: =+DO31*1.1 -> 781.26048 | DQ31: =+DP31*1.05 -> 820.3235 | DR31: =+DQ31*1.05 -> 861.33968 | DS31: =+DR31*1.05 -> 904.40666 | DT31: =+DS31*1.05 -> 949.627 | DU31: =+DT31*1.05 -> 997.10835
B32: Ozurdex | CB32: 110 | CC32: 106 | CD32: =428-CC32-CB32-CA32 -> 212 | CE32: 115 | CF32: 119 | CG32: 120 | CH32: 118 | CI32: 131 | CJ32: 124 | CK32: 119 | CL32: 120 | CM32: 123 | CN32: 125 | CO32: 117 | CP32: 128 | CQ32: =+CM32 -> 123 | CR32: =+CN32 -> 125 | CS32: =+CO32 -> 117 | CT32: =+CP32 -> 128 | DH32: =SUM(CA32:CD32) -> 428 | DI32: =SUM(CE32:CH32) -> 472 | DJ32: =SUM(CI32:CL32) -> 494 | DK32: =SUM(CM32:CP32) -> 493 | DL32: =+DK32 -> 493 | DM32: =+DL32 -> 493 | DN32: =+DM32 -> 493 | DO32: =+DN32 -> 493 | DP32: =+DO32 -> 493 | DQ32: =+DP32 -> 493 | DR32: =+DQ32 -> 493 | DS32: =+DR32 -> 493 | ... DU32: =+DT32 -> 493
B33: tavapadon | DK33: =SUM(CM33:CP33) -> 0 | DL33: 200 | DM33: 300 | DN33: =+DM33*1.01 -> 303 | DO33: =+DN33*1.01 -> 306.03 | DP33: =+DO33*1.01 -> 309.0903 | DQ33: =+DP33*1.01 -> 312.1812 | DR33: =+DQ33*1.01 -> 315.30302 | DS33: =+DR33*1.01 -> 318.45605 | DT33: =+DS33*1.01 -> 321.64061 | DU33: =+DT33*0.1 -> 32.164061
B34: Vyalev | CM34: 63 | CN34: 98 | CO34: 138 | CP34: 183 | CQ34: =+CP34+10 -> 193 | CR34: =+CQ34+10 -> 203 | CS34: =+CR34+10 -> 213 | CT34: =+CS34+10 -> 223 | DK34: =SUM(CM34:CP34) -> 482 | DL34: 150 | DM34: 300 | DN34: 450 | DO34: 600 | DP34: 700 | DQ34: 800 | DR34: 900 | DS34: 1000 | DT34: =+DS34 -> 1000 | DU34: =+DT34 -> 1000
B35: Lo Loestrin | BG35: 0 | BH35: 0 | BI35: 0 | BJ35: 0 | BK35: 0 | BL35: 0 | BM35: 0 | BN35: 0 | BO35: 0 | BP35: 0 | BQ35: 0 | BR35: 0 | BS35: 0 | BT35: 80 | DD35: =SUM(BK35:BN35) -> 0 | DE35: =SUM(BO35:BR35) -> 0 | DF35: =SUM(BS35:BV35) -> 80
B36: Orilissa | BG36: 0 | BH36: 0 | BI36: 0 | BJ36: 0 | BK36: 0 | BL36: 0 | BM36: 0 | BN36: 0 | BO36: 0 | BP36: 19 | BQ36: 27 | BR36: 34 | BS36: 31 | BT36: 31 | DD36: =SUM(BK36:BN36) -> 0 | DE36: =SUM(BO36:BR36) -> 80 | DF36: =SUM(BS36:BV36) -> 62
B37: leuprolide | G37: 50 | H37: 43 | I37: 50 | J37: 54 | K37: 52 | L37: 57 | M37: =219-N37-L37-K37 -> 56 | N37: 54 | O37: 53 | P37: 58 | Q37: =168-P37-O37 -> 57 | R37: 61
B38: lansoprazole | G38: 37 | H38: 30 | I38: 35 | J38: 41 | K38: 36 | L38: 37 | M38: =154-L38-K38-N38 -> 40 | N38: 41 | O38: 40 | P38: 44 | Q38: =127-P38-O38 -> 43 | R38: 46
B39: Prevacid | G39: 700 | H39: 706 | I39: 711 | J39: 475 | K39: 590 | L39: 337 | M39: =2501-L39-K39-N39 -> 942 | N39: 632 | O39: 616 | P39: 663 | Q39: =1891-P39-O39 -> 612 | R39: 709
B40: Lupron | G40: 180 | H40: 182 | I40: 202 | J40: 206 | K40: 171 | L40: 174 | M40: =699-L40-K40-N40 -> 181 | N40: 173 | O40: 168 | P40: 159 | Q40: =499-P40-O40 -> 172 | R40: 164 | W40: =218-X40 -> 64 | X40: 154 | Y40: 221 | Z40: 213 | AA40: =390-AB40 -> 193 | AB40: 197 | AC40: 195 | AD40: 215 | AE40: 172 | AF40: 187 | AG40: 189 | AH40: 200 | AI40: 184 | AJ40: 205 | AK40: =810-AJ40-AI40-AL40 -> 213 | AL40: 208 | AM40: 199 | AN40: 200 | AO40: 189 | AP40: 211 | AQ40: 181 | AR40: 199 | AS40: 196 | AT40: 209 | AU40: 189 | AV40: 186 | AW40: 196 | AX40: 207 | AY40: 192 | AZ40: 198 | BA40: 201 | BB40: 235 | BC40: 190 | BD40: 219 | BE40: 193 | BF40: 219 | BG40: 194 | BH40: 210 | BI40: 201 | BJ40: 224 | BK40: 219 | BL40: 223 | BM40: 214 | BN40: 236 | BO40: 229 | BP40: 209 | BQ40: 230 | BR40: 219 | BS40: 233 | BT40: 205 | CX40: 800 | CY40: 785 | CZ40: 778 | DA40: 826 | DB40: 821 | DC40: 829 | DD40: =SUM(BK40:BN40) -> 892 | DE40: =SUM(BO40:BR40) -> 887 | DF40: =SUM(BS40:BV40) -> 438
B41: Synthroid | G41: 180 | H41: 189 | I41: 165 | J41: 154 | K41: 136 | L41: 127 | M41: =554-L41-K41-N41 -> 135 | N41: 156 | O41: 126 | P41: 149 | Q41: =403-P41-O41 -> 128 | R41: 132 | S41: 129 | T41: 121 | U41: 130 | V41: 153 | W41: 115 | X41: 138 | Y41: 129 | Z41: 142 | AA41: =220-AB41 -> 104 | AB41: 116 | AC41: 134 | AD41: 148 | AE41: 123 | AF41: 129 | AG41: 143 | AH41: 160 | AI41: 145 | AJ41: 169 | AK41: =638-AJ41-AI41-AL41 -> 161 | AL41: 163 | AM41: 155 | AN41: 149 | AO41: 157 | AP41: 194 | AQ41: 119 | AR41: 153 | AS41: 161 | AT41: 189 | AU41: 157 | AV41: 166 | AW41: 200 | AX41: 186 | AY41: 186 | AZ41: 187 | BA41: 188 | BB41: 194 | BC41: 182 | BD41: 188 | BE41: 188 | BF41: 205 | BG41: 192 | BH41: 193 | BI41: 191 | BJ41: 205 | BK41: 182 | BL41: 193 | BM41: 192 | BN41: 209 | BO41: 182 | BP41: 203 | BQ41: 197 | BR41: 204 | BS41: 205 | BT41: 183 | CX41: 551 | CY41: 622 | CZ41: 709 | DA41: 755 | DB41: 763 | DC41: 781 | DD41: =SUM(BK41:BN41) -> 776 | DE41: =SUM(BO41:BR41) -> 786 | DF41: =SUM(BS41:BV41) -> 388
...

Sheet Skyrizi
A1: Main
B2: Brand | C2: Skyrizi, fka ABBV-006
B3: Generic | C3: risankizumab
B4: MOA | C4: IL-23
B5: Indication | C5: Crohn's, Psoriasis, Psoriatic Arthritis, UC (FDA/EC approved)
B6: Economics | C6: Boehringer Ingelheim
B7: Approval | C7: BLA 761105 approved 4/23/2019
B8: Clinical Trials
C9: Phase III "INSPIRE" UC induction
C12: Phase III "COMMAND" UC maintenance
C15: Phase III "SEQUENCE" vs Stelara Crohn's

Sheet Imbruvica
A1: Main
B2: Brand | C2: Imbruvica
B3: Generic | C3: ibrutinib
B4: Indication | C4: GvHD, MCL, CLL, MZL, WM
B5: MOA | C5: BTK
B6: IP | C6: 6/28/27 expiry
B7: Approval | C7: NDA 205552 approved 11/13/13
B8: Economics | C8: J&J international profit share

Sheet Emrelis
A1: Main
B2: Brand | C2: Emrelis
B3: Generic | C3: telisotuzumab vedotin
B4: Indication | C4: EGFR wild type NSCLC with c-Met overexpression
B5: Regulatory | C5: AA for 2L NSCLC with high c-Met
B6: MOA | C6: c-Met ADC
C7: c-Met is overexpressed in 25% of EGFRwt nsNSCLC according to the company
B8: Clinical Trials
C9: Phase III "TeliMET NSCLC-01"
C14: Phase II "LUMINOSITY"

Sheet ABBV-400
A1: Main
B2: Brand | C2: ABBV-400
B3: Generic | C3: telisotuzumab adizutecan
B4: Regulatory

Sheet Humira
A1: Main
B2: Brand Name | C2: Humira, fka D2E7
B3: Generic Name | C3: adalimumab
B4: Indications | C4: Rheumatoid Arthritis, Psoriasis, Crohn's, Ulcerative Colitis, Hidradenitis Suppurativa, Ankylosing Spondylitis, Non-Infection Uveitis, JIA
B5: MOA | C5: fully human anti-TNF mab
B6: IP | C6: Discovered via phage display
B7: Approval | C7: BLA 125057 approval 12/31/2002
B8: Economics | C8: Abbott acquired Knoll (BASF Pharma). Cambridge Antibody Technology had a royalty and was acquired by AstraZeneca.
B9: Clinical Trials

Sheet Rinvoq
A1: Main
B2: Brand | C2: Rinvoq, fka ABT-494
B3: Generic | C3: upadacitinib
B4: MOA | C4: JAK1 selective
B5: IP | C5: 8962629 expires 2031
B6: Indication | C6: Giant Cell Arteritis - 9th US indication
C7: GCA EMA filed
C8: Rheumatoid Arthritis approved (US, EU)
C9: Ulcerative Colitis approved (US, EU)
C10: PsA approved (US, EU)
B11: Clinical Trials
C12: Phase III "Measure Up 1" atopic dermatitis
C13: EASI H&N <1 was 27% for placebo, 68% for 15mg, 76% for 30mg
C15: Phase III "Measure Up 2" atopic dermatitis
C17: Phase III "LEVEL UP" vs. dupilumab atopic dermatitis
C19: Phase III "AD-VISE" atopic dermatitis (real world study)
C20: Phase III "UP-TAINED" atopic dermatitis (real world study)
C22: Crohn's Phase III
C23: SELECT-COMPARE
C24: SELECT-CHOICE
C25: SELET-AXIS 2
C26: Phase III "U-ACHIEVE" UC
C27: Phase III "U-EXCEL" UC
... C34: met PE

Sheet Botox
A1: Main
B2: Brand | C2: Botox, Botox Cosmetic
B3: Generic | C3: OnabotulinumtoxinA
B4: Indication | C4: Forehead lines, frown lines, crow's feet
C5: Masseter muscle prominence approved in China
C6: Platysma bands (jawline/neck) FDA approved 10/18/24
B7: Approval | C7: 33581
B8: MOA | C8: Core botulinum neurotoxin is 150kDa
B9: Competition | C9: Dysport, Xeomin, biosimilars, RVNC, Evolus, Hugel

Sheet Elahere
A1: Main
B2: Brand Name | C2: Elahere
B3: Generic Name | C3: mirvetuximab soravtansine
B4: Indication | C4: FRalpha-positive ovarian cancer
B5: Regulatory | C5: FDA approved 11/14/2022. CHMP positive opinion on MIRASOL
B6: Economics | C6: acquired ImmunoGen
B7: Administration | C7: IV
B8: MOA | C8: FRalpha mab with DM4
B9: Clinical Trials
C10: Phase III "MIRASOL" mirv vs. IC - Fralpha+ prOC
C15: Phase II "PICCOLO" monotherapy FRalpha+ platinum-sensitive OC
C16: 52% ORR, 8.25m DOR
C20: Phase II "SORAYA" n=106 2L+ Fralpha+ prOC
C21: 32% ORR, 6.9mo DOR; 4.8% CR

Sheet Qulipta
A1: Main
B2: Brand | C2: Qulipta
B3: Generic | C3: atogepant
B4: Indication | C4: Migraine
B5: Clinical Trials
C6: Phase III "TEMPLE" vs. topiramate
C7: beat onsafety and efficacy

Sheet emraclidine
A1: Main
B2: Brand
B3: Generic | C3: emraclidine
B4: Indication | C4: Schizophrenia
B5: Economics | C5: acquired Cerevel for this asset
B6: MOA | C6: M4 pam
B7: Clinical Trials
C8: Phase II "EMPOWER-1" schizophrenia
C9: placebo | D9: -13.5
C10: 10mg | D10: -14.7
C11: 30mg | D11: -16.5
C13: Phase II "EMPOWER-2" schizophrenia
C14: placebo | D14: -16.1
C15: 10mg | D15: -18.5
C16: 30mg | D16: -14.2

Sheet Epkinly
A1: Main
B2: Brand | C2: Epkinly, Tepkinly
B3: Generic | C3: epcoritamab
B4: Indication | C4: r/r (3L+) FL
B5: Approval | C5: FDA approval 2024, CHMP positive opinion, EC approval 2024
B6: Administration | C6: subcutaneous
B7: Mechanism | C7: bispecific
B8: Economics | C8: GMAB
B9: Clinical Trials
C10: Phase I/II "EPCORE NHL-1" n=157 r/r FL - NCT03625037
C11: GCT3013-01, single-arm, open-label, monotherapy
C12: 3 median prior therapies
C13: 63% ORR, 39% CR
D14: updated data: 59% ORR, 41% CR with median CR duration 36 months
C16: Phase Ib/II "EPCORE NHL-2" n=44 1L DLBCL - NCT04663347
C17: epcoritamab+R-CHOP had 100% ORR, 87% CR, 83% remain in CR after 2 years
D19: Arm 2: n=111 lenalidomide+rituximab R/R FL
D20: 96% ORR, 87% CR
C22: Phase III "EPCORE FL-1" epcori+ritux+lena vs. ritux+lena - NCT05409066
C23: PE: PFS
C25: NCT05578976
C26: NCT05409066
C27: NCT06191744
C28: NCT06508658

Sheet Vyalev
A1: Main
B2: Brand | C2: Vyalev, fka ABBV-951
B3: Generic | C3: foscarbidopa, foslevodopa
B4: Administration | C4: subcutaneous 24-hour
B5: Indication | C5: Parkinson's
B6: Regulatory | C6: FDA approval 10/17/2024

Sheet Venclexta
A1: Main
B2: Brand | C2: Venclexta
B3: Generic | C3: venetoclax
B4: Indication | C4: Chronic Lymphocytic Leukemia, Acute Myeloid Leukemia
B5: MOA | C5: Bcl-2 inhibitor
B6: Economics | C6: Roche
B7: Administration | C7: oral
B8: Regulatory | C8: NDA 208573 approved 4/11/2016
B9: Clinical Trials
C11: Phase III "VERONA" 1L high-risk MDS with azacitidine
C12: PE: OS failed
C16: Phase III "AMPLIFY" Venclexta + acalabrutinib 1L CLL
C17: PFS beat chemoimmunotherapy

Sheet tavapadon
A1: Main
B2: Brand
B3: Generic | C3: tavapadon
B4: Indication | C4: early PD
B5: Mechanism | C5: D1/D5 agonist
B6: Regulatory | C6: filing NDA in 2025
B7: Competition | C7: rotigotine, ropinirole, apomorphine, pramipexole
B8: Clinical Trials
C9: Phase III "TEMPO-1" fixed-dose Parkinson's - NCT04201093
C10: MDS-UPDRS Part II+III at week 26 vs. placebo
C11: placebo +1.8, tavapadon -9.7 and -10.2 at week 26
C13: Phase III "TEMPO-2" flexible-dose Parksinon's - NCT04223193
C14: met PE MDS-UPDRS Part II/III
C15: placebo -1.2, tavapadon -10.3, p<0.0001
C18: Phase III TEMPO-3 adjunctive Parkinson's - NCT04542499
C23: TEMPO-4 - NCT04760769
